[2025-04-22 18:35:08] ERROR in my_logger: Error in GET method: name 'Pattern_typeSerializer' is not defined
Traceback (most recent call last):
  File "C:\Users\emedhub\Desktop\html\Project\BE\castingiq jango\castingiq\master\views.py", line 29, in post
    serializer = pattern_typeSerializer(data=data)
  File "C:\Users\emedhub\Desktop\html\Project\BE\castingiq jango\castingiq\master\serializer.py", line 13, in __init__
    super(Pattern_typeSerializer, self).__init__(*args, **kwargs)
NameError: name 'Pattern_typeSerializer' is not defined
[2025-04-22 18:47:53] ERROR in my_logger: Error in GET method: name 'Pattern_typeSerializer' is not defined
Traceback (most recent call last):
  File "C:\Users\emedhub\Desktop\html\Project\BE\castingiq jango\castingiq\master\views.py", line 29, in post
    serializer = pattern_typeSerializer(data=data)
  File "C:\Users\emedhub\Desktop\html\Project\BE\castingiq jango\castingiq\master\serializer.py", line 13, in __init__
    super(Pattern_typeSerializer, self).__init__(*args, **kwargs)
NameError: name 'Pattern_typeSerializer' is not defined
[2025-04-22 18:53:29] ERROR in my_logger: Error in GET method: 'company'
Traceback (most recent call last):
  File "C:\Users\emedhub\Desktop\html\Project\BE\castingiq jango\castingiq\master\views.py", line 31, in post
    is_valid = serializer.is_valid(raise_exception=True)
  File "C:\Users\emedhub\AppData\Local\Programs\Python\Python310\lib\site-packages\rest_framework\serializers.py", line 225, in is_valid
    self._validated_data = self.run_validation(self.initial_data)
  File "C:\Users\emedhub\AppData\Local\Programs\Python\Python310\lib\site-packages\rest_framework\serializers.py", line 447, in run_validation
    value = self.validate(value)
  File "C:\Users\emedhub\Desktop\html\Project\BE\castingiq jango\castingiq\master\serializer.py", line 19, in validate
    return CodeAutoGenerate.generate_code(self.Meta.model, attrs['company'], attrs, prefix='EMT', id=self.id)
KeyError: 'company'

During handling of the above exception, another exception occurred:

Traceback (most recent call last):
  File "C:\Users\emedhub\Desktop\html\Project\BE\castingiq jango\castingiq\master\views.py", line 33, in post
    serializer.is_valid()
  File "C:\Users\emedhub\AppData\Local\Programs\Python\Python310\lib\site-packages\rest_framework\serializers.py", line 225, in is_valid
    self._validated_data = self.run_validation(self.initial_data)
  File "C:\Users\emedhub\AppData\Local\Programs\Python\Python310\lib\site-packages\rest_framework\serializers.py", line 447, in run_validation
    value = self.validate(value)
  File "C:\Users\emedhub\Desktop\html\Project\BE\castingiq jango\castingiq\master\serializer.py", line 19, in validate
    return CodeAutoGenerate.generate_code(self.Meta.model, attrs['company'], attrs, prefix='EMT', id=self.id)
KeyError: 'company'
[2025-04-22 19:02:13] ERROR in my_logger: Error in GET method: 'company'
Traceback (most recent call last):
  File "C:\Users\emedhub\Desktop\html\Project\BE\castingiq jango\castingiq\master\views.py", line 31, in post
    is_valid = serializer.is_valid(raise_exception=True)
  File "C:\Users\emedhub\AppData\Local\Programs\Python\Python310\lib\site-packages\rest_framework\serializers.py", line 225, in is_valid
    self._validated_data = self.run_validation(self.initial_data)
  File "C:\Users\emedhub\AppData\Local\Programs\Python\Python310\lib\site-packages\rest_framework\serializers.py", line 447, in run_validation
    value = self.validate(value)
  File "C:\Users\emedhub\Desktop\html\Project\BE\castingiq jango\castingiq\master\serializer.py", line 22, in validate
    return CodeAutoGenerate.generate_code(self.Meta.model, attrs['company'], attrs, prefix='EMT', id=self.id)
KeyError: 'company'

During handling of the above exception, another exception occurred:

Traceback (most recent call last):
  File "C:\Users\emedhub\Desktop\html\Project\BE\castingiq jango\castingiq\master\views.py", line 33, in post
    serializer.is_valid()
  File "C:\Users\emedhub\AppData\Local\Programs\Python\Python310\lib\site-packages\rest_framework\serializers.py", line 225, in is_valid
    self._validated_data = self.run_validation(self.initial_data)
  File "C:\Users\emedhub\AppData\Local\Programs\Python\Python310\lib\site-packages\rest_framework\serializers.py", line 447, in run_validation
    value = self.validate(value)
  File "C:\Users\emedhub\Desktop\html\Project\BE\castingiq jango\castingiq\master\serializer.py", line 22, in validate
    return CodeAutoGenerate.generate_code(self.Meta.model, attrs['company'], attrs, prefix='EMT', id=self.id)
KeyError: 'company'
[2025-04-26 11:26:35] ERROR in my_logger: Error in GET method: CodeAutoGenerate.generate_code() missing 1 required positional argument: 'attrs'
Traceback (most recent call last):
  File "C:\Users\emedhub\Desktop\html\Project\BE\castingiq jango\castingiq\master\views.py", line 31, in post
    is_valid = serializer.is_valid(raise_exception=True)
  File "C:\Users\emedhub\AppData\Local\Programs\Python\Python310\lib\site-packages\rest_framework\serializers.py", line 227, in is_valid
    self._validated_data = self.run_validation(self.initial_data)
  File "C:\Users\emedhub\AppData\Local\Programs\Python\Python310\lib\site-packages\rest_framework\serializers.py", line 429, in run_validation
    value = self.validate(value)
  File "C:\Users\emedhub\Desktop\html\Project\BE\castingiq jango\castingiq\master\serializer.py", line 19, in validate
    return CodeAutoGenerate.generate_code(self.Meta.model, attrs, prefix='EMT', id=self.id)
TypeError: CodeAutoGenerate.generate_code() missing 1 required positional argument: 'attrs'

During handling of the above exception, another exception occurred:

Traceback (most recent call last):
  File "C:\Users\emedhub\Desktop\html\Project\BE\castingiq jango\castingiq\master\views.py", line 33, in post
    serializer.is_valid()
  File "C:\Users\emedhub\AppData\Local\Programs\Python\Python310\lib\site-packages\rest_framework\serializers.py", line 227, in is_valid
    self._validated_data = self.run_validation(self.initial_data)
  File "C:\Users\emedhub\AppData\Local\Programs\Python\Python310\lib\site-packages\rest_framework\serializers.py", line 429, in run_validation
    value = self.validate(value)
  File "C:\Users\emedhub\Desktop\html\Project\BE\castingiq jango\castingiq\master\serializer.py", line 19, in validate
    return CodeAutoGenerate.generate_code(self.Meta.model, attrs, prefix='EMT', id=self.id)
TypeError: CodeAutoGenerate.generate_code() missing 1 required positional argument: 'attrs'
[2025-04-26 11:41:38] ERROR in my_logger: Error in GET method: Cannot call `.is_valid()` as no `data=` keyword argument was passed when instantiating the serializer instance.
Traceback (most recent call last):
  File "C:\Users\emedhub\Desktop\html\Project\BE\castingiq jango\castingiq\master\views.py", line 19, in get
    is_valid = serializer.is_valid()
  File "C:\Users\emedhub\AppData\Local\Programs\Python\Python310\lib\site-packages\rest_framework\serializers.py", line 741, in is_valid
    assert hasattr(self, 'initial_data'), (
AssertionError: Cannot call `.is_valid()` as no `data=` keyword argument was passed when instantiating the serializer instance.
[2025-04-26 11:58:09] ERROR in my_logger: Error in GET method: Cannot resolve keyword 'i' into field. Choices are: code, created_by, created_date, description, id, is_active, is_draft, modified_by, modified_date, name, notes
Traceback (most recent call last):
  File "C:\Users\emedhub\Desktop\html\Project\BE\castingiq jango\castingiq\master\views.py", line 18, in get
    serializer = pattern_typeSerializer(data=data,many=True)
  File "C:\Users\emedhub\AppData\Local\Programs\Python\Python310\lib\site-packages\rest_framework\serializers.py", line 122, in __new__
    return cls.many_init(*args, **kwargs)
  File "C:\Users\emedhub\AppData\Local\Programs\Python\Python310\lib\site-packages\rest_framework\serializers.py", line 149, in many_init
    child_serializer = cls(*args, **kwargs)
  File "C:\Users\emedhub\Desktop\html\Project\BE\castingiq jango\castingiq\master\serializer.py", line 12, in __init__
    self.id = kwargs.get('data', {}).get('id')
  File "C:\Users\emedhub\AppData\Local\Programs\Python\Python310\lib\site-packages\django\db\models\query.py", line 635, in get
    clone = self._chain() if self.query.combinator else self.filter(*args, **kwargs)
  File "C:\Users\emedhub\AppData\Local\Programs\Python\Python310\lib\site-packages\django\db\models\query.py", line 1476, in filter
    return self._filter_or_exclude(False, args, kwargs)
  File "C:\Users\emedhub\AppData\Local\Programs\Python\Python310\lib\site-packages\django\db\models\query.py", line 1494, in _filter_or_exclude
    clone._filter_or_exclude_inplace(negate, args, kwargs)
  File "C:\Users\emedhub\AppData\Local\Programs\Python\Python310\lib\site-packages\django\db\models\query.py", line 1501, in _filter_or_exclude_inplace
    self._query.add_q(Q(*args, **kwargs))
  File "C:\Users\emedhub\AppData\Local\Programs\Python\Python310\lib\site-packages\django\db\models\sql\query.py", line 1613, in add_q
    clause, _ = self._add_q(q_object, self.used_aliases)
  File "C:\Users\emedhub\AppData\Local\Programs\Python\Python310\lib\site-packages\django\db\models\sql\query.py", line 1645, in _add_q
    child_clause, needed_inner = self.build_filter(
  File "C:\Users\emedhub\AppData\Local\Programs\Python\Python310\lib\site-packages\django\db\models\sql\query.py", line 1495, in build_filter
    lookups, parts, reffed_expression = self.solve_lookup_type(arg, summarize)
  File "C:\Users\emedhub\AppData\Local\Programs\Python\Python310\lib\site-packages\django\db\models\sql\query.py", line 1307, in solve_lookup_type
    _, field, _, lookup_parts = self.names_to_path(lookup_splitted, self.get_meta())
  File "C:\Users\emedhub\AppData\Local\Programs\Python\Python310\lib\site-packages\django\db\models\sql\query.py", line 1772, in names_to_path
    raise FieldError(
django.core.exceptions.FieldError: Cannot resolve keyword 'i' into field. Choices are: code, created_by, created_date, description, id, is_active, is_draft, modified_by, modified_date, name, notes
[2025-04-26 11:58:57] ERROR in my_logger: Error in GET method: Cannot resolve keyword 'i' into field. Choices are: code, created_by, created_date, description, id, is_active, is_draft, modified_by, modified_date, name, notes
Traceback (most recent call last):
  File "C:\Users\emedhub\Desktop\html\Project\BE\castingiq jango\castingiq\master\views.py", line 18, in get
    serializer = pattern_typeSerializer(data=data,many=True)
  File "C:\Users\emedhub\AppData\Local\Programs\Python\Python310\lib\site-packages\rest_framework\serializers.py", line 122, in __new__
    return cls.many_init(*args, **kwargs)
  File "C:\Users\emedhub\AppData\Local\Programs\Python\Python310\lib\site-packages\rest_framework\serializers.py", line 149, in many_init
    child_serializer = cls(*args, **kwargs)
  File "C:\Users\emedhub\Desktop\html\Project\BE\castingiq jango\castingiq\master\serializer.py", line 12, in __init__
    self.id = kwargs.get('data', {}).get('id')
  File "C:\Users\emedhub\AppData\Local\Programs\Python\Python310\lib\site-packages\django\db\models\query.py", line 635, in get
    clone = self._chain() if self.query.combinator else self.filter(*args, **kwargs)
  File "C:\Users\emedhub\AppData\Local\Programs\Python\Python310\lib\site-packages\django\db\models\query.py", line 1476, in filter
    return self._filter_or_exclude(False, args, kwargs)
  File "C:\Users\emedhub\AppData\Local\Programs\Python\Python310\lib\site-packages\django\db\models\query.py", line 1494, in _filter_or_exclude
    clone._filter_or_exclude_inplace(negate, args, kwargs)
  File "C:\Users\emedhub\AppData\Local\Programs\Python\Python310\lib\site-packages\django\db\models\query.py", line 1501, in _filter_or_exclude_inplace
    self._query.add_q(Q(*args, **kwargs))
  File "C:\Users\emedhub\AppData\Local\Programs\Python\Python310\lib\site-packages\django\db\models\sql\query.py", line 1613, in add_q
    clause, _ = self._add_q(q_object, self.used_aliases)
  File "C:\Users\emedhub\AppData\Local\Programs\Python\Python310\lib\site-packages\django\db\models\sql\query.py", line 1645, in _add_q
    child_clause, needed_inner = self.build_filter(
  File "C:\Users\emedhub\AppData\Local\Programs\Python\Python310\lib\site-packages\django\db\models\sql\query.py", line 1495, in build_filter
    lookups, parts, reffed_expression = self.solve_lookup_type(arg, summarize)
  File "C:\Users\emedhub\AppData\Local\Programs\Python\Python310\lib\site-packages\django\db\models\sql\query.py", line 1307, in solve_lookup_type
    _, field, _, lookup_parts = self.names_to_path(lookup_splitted, self.get_meta())
  File "C:\Users\emedhub\AppData\Local\Programs\Python\Python310\lib\site-packages\django\db\models\sql\query.py", line 1772, in names_to_path
    raise FieldError(
django.core.exceptions.FieldError: Cannot resolve keyword 'i' into field. Choices are: code, created_by, created_date, description, id, is_active, is_draft, modified_by, modified_date, name, notes
[2025-04-26 12:01:52] ERROR in my_logger: Error in GET method: Cannot resolve keyword 'i' into field. Choices are: code, created_by, created_date, description, id, is_active, is_draft, modified_by, modified_date, name, notes
Traceback (most recent call last):
  File "C:\Users\emedhub\Desktop\html\Project\BE\castingiq jango\castingiq\master\views.py", line 18, in get
    serializer = pattern_typeSerializer(data=data,many=True)
  File "C:\Users\emedhub\AppData\Local\Programs\Python\Python310\lib\site-packages\rest_framework\serializers.py", line 122, in __new__
    return cls.many_init(*args, **kwargs)
  File "C:\Users\emedhub\AppData\Local\Programs\Python\Python310\lib\site-packages\rest_framework\serializers.py", line 149, in many_init
    child_serializer = cls(*args, **kwargs)
  File "C:\Users\emedhub\Desktop\html\Project\BE\castingiq jango\castingiq\master\serializer.py", line 12, in __init__
    self.id = kwargs.get('data', {}).get('id')
  File "C:\Users\emedhub\AppData\Local\Programs\Python\Python310\lib\site-packages\django\db\models\query.py", line 635, in get
    clone = self._chain() if self.query.combinator else self.filter(*args, **kwargs)
  File "C:\Users\emedhub\AppData\Local\Programs\Python\Python310\lib\site-packages\django\db\models\query.py", line 1476, in filter
    return self._filter_or_exclude(False, args, kwargs)
  File "C:\Users\emedhub\AppData\Local\Programs\Python\Python310\lib\site-packages\django\db\models\query.py", line 1494, in _filter_or_exclude
    clone._filter_or_exclude_inplace(negate, args, kwargs)
  File "C:\Users\emedhub\AppData\Local\Programs\Python\Python310\lib\site-packages\django\db\models\query.py", line 1501, in _filter_or_exclude_inplace
    self._query.add_q(Q(*args, **kwargs))
  File "C:\Users\emedhub\AppData\Local\Programs\Python\Python310\lib\site-packages\django\db\models\sql\query.py", line 1613, in add_q
    clause, _ = self._add_q(q_object, self.used_aliases)
  File "C:\Users\emedhub\AppData\Local\Programs\Python\Python310\lib\site-packages\django\db\models\sql\query.py", line 1645, in _add_q
    child_clause, needed_inner = self.build_filter(
  File "C:\Users\emedhub\AppData\Local\Programs\Python\Python310\lib\site-packages\django\db\models\sql\query.py", line 1495, in build_filter
    lookups, parts, reffed_expression = self.solve_lookup_type(arg, summarize)
  File "C:\Users\emedhub\AppData\Local\Programs\Python\Python310\lib\site-packages\django\db\models\sql\query.py", line 1307, in solve_lookup_type
    _, field, _, lookup_parts = self.names_to_path(lookup_splitted, self.get_meta())
  File "C:\Users\emedhub\AppData\Local\Programs\Python\Python310\lib\site-packages\django\db\models\sql\query.py", line 1772, in names_to_path
    raise FieldError(
django.core.exceptions.FieldError: Cannot resolve keyword 'i' into field. Choices are: code, created_by, created_date, description, id, is_active, is_draft, modified_by, modified_date, name, notes
[2025-04-26 12:09:06] ERROR in my_logger: Error in GET method: Cannot resolve keyword 'i' into field. Choices are: code, created_by, created_date, description, id, is_active, is_draft, modified_by, modified_date, name, notes
Traceback (most recent call last):
  File "C:\Users\emedhub\Desktop\html\Project\BE\castingiq jango\castingiq\master\views.py", line 18, in get
    serializer = pattern_typeSerializer(data=data,many=True)
  File "C:\Users\emedhub\AppData\Local\Programs\Python\Python310\lib\site-packages\rest_framework\serializers.py", line 122, in __new__
    return cls.many_init(*args, **kwargs)
  File "C:\Users\emedhub\AppData\Local\Programs\Python\Python310\lib\site-packages\rest_framework\serializers.py", line 149, in many_init
    child_serializer = cls(*args, **kwargs)
  File "C:\Users\emedhub\Desktop\html\Project\BE\castingiq jango\castingiq\master\serializer.py", line 12, in __init__
    self.id = kwargs.get('data', {}).get('id')
  File "C:\Users\emedhub\AppData\Local\Programs\Python\Python310\lib\site-packages\django\db\models\query.py", line 635, in get
    clone = self._chain() if self.query.combinator else self.filter(*args, **kwargs)
  File "C:\Users\emedhub\AppData\Local\Programs\Python\Python310\lib\site-packages\django\db\models\query.py", line 1476, in filter
    return self._filter_or_exclude(False, args, kwargs)
  File "C:\Users\emedhub\AppData\Local\Programs\Python\Python310\lib\site-packages\django\db\models\query.py", line 1494, in _filter_or_exclude
    clone._filter_or_exclude_inplace(negate, args, kwargs)
  File "C:\Users\emedhub\AppData\Local\Programs\Python\Python310\lib\site-packages\django\db\models\query.py", line 1501, in _filter_or_exclude_inplace
    self._query.add_q(Q(*args, **kwargs))
  File "C:\Users\emedhub\AppData\Local\Programs\Python\Python310\lib\site-packages\django\db\models\sql\query.py", line 1613, in add_q
    clause, _ = self._add_q(q_object, self.used_aliases)
  File "C:\Users\emedhub\AppData\Local\Programs\Python\Python310\lib\site-packages\django\db\models\sql\query.py", line 1645, in _add_q
    child_clause, needed_inner = self.build_filter(
  File "C:\Users\emedhub\AppData\Local\Programs\Python\Python310\lib\site-packages\django\db\models\sql\query.py", line 1495, in build_filter
    lookups, parts, reffed_expression = self.solve_lookup_type(arg, summarize)
  File "C:\Users\emedhub\AppData\Local\Programs\Python\Python310\lib\site-packages\django\db\models\sql\query.py", line 1307, in solve_lookup_type
    _, field, _, lookup_parts = self.names_to_path(lookup_splitted, self.get_meta())
  File "C:\Users\emedhub\AppData\Local\Programs\Python\Python310\lib\site-packages\django\db\models\sql\query.py", line 1772, in names_to_path
    raise FieldError(
django.core.exceptions.FieldError: Cannot resolve keyword 'i' into field. Choices are: code, created_by, created_date, description, id, is_active, is_draft, modified_by, modified_date, name, notes
[2025-04-26 12:10:12] ERROR in my_logger: Error in GET method: Cannot resolve keyword 'i' into field. Choices are: code, created_by, created_date, description, id, is_active, is_draft, modified_by, modified_date, name, notes
Traceback (most recent call last):
  File "C:\Users\emedhub\Desktop\html\Project\BE\castingiq jango\castingiq\master\views.py", line 18, in get
    serializer = pattern_typeSerializer(data=data,many=True)
  File "C:\Users\emedhub\AppData\Local\Programs\Python\Python310\lib\site-packages\rest_framework\serializers.py", line 122, in __new__
    return cls.many_init(*args, **kwargs)
  File "C:\Users\emedhub\AppData\Local\Programs\Python\Python310\lib\site-packages\rest_framework\serializers.py", line 149, in many_init
    child_serializer = cls(*args, **kwargs)
  File "C:\Users\emedhub\Desktop\html\Project\BE\castingiq jango\castingiq\master\serializer.py", line 12, in __init__
    self.id = kwargs.get('data', {}).get('id')
  File "C:\Users\emedhub\AppData\Local\Programs\Python\Python310\lib\site-packages\django\db\models\query.py", line 635, in get
    clone = self._chain() if self.query.combinator else self.filter(*args, **kwargs)
  File "C:\Users\emedhub\AppData\Local\Programs\Python\Python310\lib\site-packages\django\db\models\query.py", line 1476, in filter
    return self._filter_or_exclude(False, args, kwargs)
  File "C:\Users\emedhub\AppData\Local\Programs\Python\Python310\lib\site-packages\django\db\models\query.py", line 1494, in _filter_or_exclude
    clone._filter_or_exclude_inplace(negate, args, kwargs)
  File "C:\Users\emedhub\AppData\Local\Programs\Python\Python310\lib\site-packages\django\db\models\query.py", line 1501, in _filter_or_exclude_inplace
    self._query.add_q(Q(*args, **kwargs))
  File "C:\Users\emedhub\AppData\Local\Programs\Python\Python310\lib\site-packages\django\db\models\sql\query.py", line 1613, in add_q
    clause, _ = self._add_q(q_object, self.used_aliases)
  File "C:\Users\emedhub\AppData\Local\Programs\Python\Python310\lib\site-packages\django\db\models\sql\query.py", line 1645, in _add_q
    child_clause, needed_inner = self.build_filter(
  File "C:\Users\emedhub\AppData\Local\Programs\Python\Python310\lib\site-packages\django\db\models\sql\query.py", line 1495, in build_filter
    lookups, parts, reffed_expression = self.solve_lookup_type(arg, summarize)
  File "C:\Users\emedhub\AppData\Local\Programs\Python\Python310\lib\site-packages\django\db\models\sql\query.py", line 1307, in solve_lookup_type
    _, field, _, lookup_parts = self.names_to_path(lookup_splitted, self.get_meta())
  File "C:\Users\emedhub\AppData\Local\Programs\Python\Python310\lib\site-packages\django\db\models\sql\query.py", line 1772, in names_to_path
    raise FieldError(
django.core.exceptions.FieldError: Cannot resolve keyword 'i' into field. Choices are: code, created_by, created_date, description, id, is_active, is_draft, modified_by, modified_date, name, notes
[2025-04-26 12:12:38] ERROR in my_logger: Error in GET method: Cannot resolve keyword 'i' into field. Choices are: code, created_by, created_date, description, id, is_active, is_draft, modified_by, modified_date, name, notes
Traceback (most recent call last):
  File "C:\Users\emedhub\Desktop\html\Project\BE\castingiq jango\castingiq\master\views.py", line 18, in get
    serializer = pattern_typeSerializer(data=data,many=False)
  File "C:\Users\emedhub\Desktop\html\Project\BE\castingiq jango\castingiq\master\serializer.py", line 12, in __init__
    self.id = kwargs.get('data', {}).get('id')
  File "C:\Users\emedhub\AppData\Local\Programs\Python\Python310\lib\site-packages\django\db\models\query.py", line 635, in get
    clone = self._chain() if self.query.combinator else self.filter(*args, **kwargs)
  File "C:\Users\emedhub\AppData\Local\Programs\Python\Python310\lib\site-packages\django\db\models\query.py", line 1476, in filter
    return self._filter_or_exclude(False, args, kwargs)
  File "C:\Users\emedhub\AppData\Local\Programs\Python\Python310\lib\site-packages\django\db\models\query.py", line 1494, in _filter_or_exclude
    clone._filter_or_exclude_inplace(negate, args, kwargs)
  File "C:\Users\emedhub\AppData\Local\Programs\Python\Python310\lib\site-packages\django\db\models\query.py", line 1501, in _filter_or_exclude_inplace
    self._query.add_q(Q(*args, **kwargs))
  File "C:\Users\emedhub\AppData\Local\Programs\Python\Python310\lib\site-packages\django\db\models\sql\query.py", line 1613, in add_q
    clause, _ = self._add_q(q_object, self.used_aliases)
  File "C:\Users\emedhub\AppData\Local\Programs\Python\Python310\lib\site-packages\django\db\models\sql\query.py", line 1645, in _add_q
    child_clause, needed_inner = self.build_filter(
  File "C:\Users\emedhub\AppData\Local\Programs\Python\Python310\lib\site-packages\django\db\models\sql\query.py", line 1495, in build_filter
    lookups, parts, reffed_expression = self.solve_lookup_type(arg, summarize)
  File "C:\Users\emedhub\AppData\Local\Programs\Python\Python310\lib\site-packages\django\db\models\sql\query.py", line 1307, in solve_lookup_type
    _, field, _, lookup_parts = self.names_to_path(lookup_splitted, self.get_meta())
  File "C:\Users\emedhub\AppData\Local\Programs\Python\Python310\lib\site-packages\django\db\models\sql\query.py", line 1772, in names_to_path
    raise FieldError(
django.core.exceptions.FieldError: Cannot resolve keyword 'i' into field. Choices are: code, created_by, created_date, description, id, is_active, is_draft, modified_by, modified_date, name, notes
[2025-04-26 12:13:00] ERROR in my_logger: Error in GET method: Cannot resolve keyword 'i' into field. Choices are: code, created_by, created_date, description, id, is_active, is_draft, modified_by, modified_date, name, notes
Traceback (most recent call last):
  File "C:\Users\emedhub\Desktop\html\Project\BE\castingiq jango\castingiq\master\views.py", line 18, in get
    serializer = pattern_typeSerializer(data=data,many=True)
  File "C:\Users\emedhub\AppData\Local\Programs\Python\Python310\lib\site-packages\rest_framework\serializers.py", line 122, in __new__
    return cls.many_init(*args, **kwargs)
  File "C:\Users\emedhub\AppData\Local\Programs\Python\Python310\lib\site-packages\rest_framework\serializers.py", line 149, in many_init
    child_serializer = cls(*args, **kwargs)
  File "C:\Users\emedhub\Desktop\html\Project\BE\castingiq jango\castingiq\master\serializer.py", line 12, in __init__
    self.id = kwargs.get('data', {}).get('id')
  File "C:\Users\emedhub\AppData\Local\Programs\Python\Python310\lib\site-packages\django\db\models\query.py", line 635, in get
    clone = self._chain() if self.query.combinator else self.filter(*args, **kwargs)
  File "C:\Users\emedhub\AppData\Local\Programs\Python\Python310\lib\site-packages\django\db\models\query.py", line 1476, in filter
    return self._filter_or_exclude(False, args, kwargs)
  File "C:\Users\emedhub\AppData\Local\Programs\Python\Python310\lib\site-packages\django\db\models\query.py", line 1494, in _filter_or_exclude
    clone._filter_or_exclude_inplace(negate, args, kwargs)
  File "C:\Users\emedhub\AppData\Local\Programs\Python\Python310\lib\site-packages\django\db\models\query.py", line 1501, in _filter_or_exclude_inplace
    self._query.add_q(Q(*args, **kwargs))
  File "C:\Users\emedhub\AppData\Local\Programs\Python\Python310\lib\site-packages\django\db\models\sql\query.py", line 1613, in add_q
    clause, _ = self._add_q(q_object, self.used_aliases)
  File "C:\Users\emedhub\AppData\Local\Programs\Python\Python310\lib\site-packages\django\db\models\sql\query.py", line 1645, in _add_q
    child_clause, needed_inner = self.build_filter(
  File "C:\Users\emedhub\AppData\Local\Programs\Python\Python310\lib\site-packages\django\db\models\sql\query.py", line 1495, in build_filter
    lookups, parts, reffed_expression = self.solve_lookup_type(arg, summarize)
  File "C:\Users\emedhub\AppData\Local\Programs\Python\Python310\lib\site-packages\django\db\models\sql\query.py", line 1307, in solve_lookup_type
    _, field, _, lookup_parts = self.names_to_path(lookup_splitted, self.get_meta())
  File "C:\Users\emedhub\AppData\Local\Programs\Python\Python310\lib\site-packages\django\db\models\sql\query.py", line 1772, in names_to_path
    raise FieldError(
django.core.exceptions.FieldError: Cannot resolve keyword 'i' into field. Choices are: code, created_by, created_date, description, id, is_active, is_draft, modified_by, modified_date, name, notes
[2025-04-26 12:20:55] ERROR in my_logger: Error in GET method: Cannot call `.is_valid()` as no `data=` keyword argument was passed when instantiating the serializer instance.
Traceback (most recent call last):
  File "C:\Users\emedhub\Desktop\html\Project\BE\castingiq jango\castingiq\master\views.py", line 19, in get
    is_valid = serializer.is_valid()
  File "C:\Users\emedhub\AppData\Local\Programs\Python\Python310\lib\site-packages\rest_framework\serializers.py", line 741, in is_valid
    assert hasattr(self, 'initial_data'), (
AssertionError: Cannot call `.is_valid()` as no `data=` keyword argument was passed when instantiating the serializer instance.
[2025-04-26 12:44:00] ERROR in my_logger: Error in GET method: 'pattern_typeSerializer' object has no attribute 'id'
Traceback (most recent call last):
  File "C:\Users\emedhub\Desktop\html\Project\BE\castingiq jango\castingiq\master\views.py", line 32, in post
    is_valid = serializer.is_valid(raise_exception=True)
  File "C:\Users\emedhub\AppData\Local\Programs\Python\Python310\lib\site-packages\rest_framework\serializers.py", line 227, in is_valid
    self._validated_data = self.run_validation(self.initial_data)
  File "C:\Users\emedhub\AppData\Local\Programs\Python\Python310\lib\site-packages\rest_framework\serializers.py", line 429, in run_validation
    value = self.validate(value)
  File "C:\Users\emedhub\Desktop\html\Project\BE\castingiq jango\castingiq\master\serializer.py", line 14, in validate
    return CodeAutoGenerate.generate_code(self.Meta.model, attrs, prefix='EMT', id=self.id)
AttributeError: 'pattern_typeSerializer' object has no attribute 'id'

During handling of the above exception, another exception occurred:

Traceback (most recent call last):
  File "C:\Users\emedhub\Desktop\html\Project\BE\castingiq jango\castingiq\master\views.py", line 34, in post
    serializer.is_valid()
  File "C:\Users\emedhub\AppData\Local\Programs\Python\Python310\lib\site-packages\rest_framework\serializers.py", line 227, in is_valid
    self._validated_data = self.run_validation(self.initial_data)
  File "C:\Users\emedhub\AppData\Local\Programs\Python\Python310\lib\site-packages\rest_framework\serializers.py", line 429, in run_validation
    value = self.validate(value)
  File "C:\Users\emedhub\Desktop\html\Project\BE\castingiq jango\castingiq\master\serializer.py", line 14, in validate
    return CodeAutoGenerate.generate_code(self.Meta.model, attrs, prefix='EMT', id=self.id)
AttributeError: 'pattern_typeSerializer' object has no attribute 'id'
[2025-04-26 12:45:09] ERROR in my_logger: Error in GET method: 'pattern_typeSerializer' object has no attribute 'id'
Traceback (most recent call last):
  File "C:\Users\emedhub\Desktop\html\Project\BE\castingiq jango\castingiq\master\views.py", line 32, in post
    is_valid = serializer.is_valid(raise_exception=True)
  File "C:\Users\emedhub\AppData\Local\Programs\Python\Python310\lib\site-packages\rest_framework\serializers.py", line 227, in is_valid
    self._validated_data = self.run_validation(self.initial_data)
  File "C:\Users\emedhub\AppData\Local\Programs\Python\Python310\lib\site-packages\rest_framework\serializers.py", line 429, in run_validation
    value = self.validate(value)
  File "C:\Users\emedhub\Desktop\html\Project\BE\castingiq jango\castingiq\master\serializer.py", line 14, in validate
    return CodeAutoGenerate.generate_code(self.Meta.model, attrs, prefix='EMT', id=self.id)
AttributeError: 'pattern_typeSerializer' object has no attribute 'id'

During handling of the above exception, another exception occurred:

Traceback (most recent call last):
  File "C:\Users\emedhub\Desktop\html\Project\BE\castingiq jango\castingiq\master\views.py", line 34, in post
    serializer.is_valid()
  File "C:\Users\emedhub\AppData\Local\Programs\Python\Python310\lib\site-packages\rest_framework\serializers.py", line 227, in is_valid
    self._validated_data = self.run_validation(self.initial_data)
  File "C:\Users\emedhub\AppData\Local\Programs\Python\Python310\lib\site-packages\rest_framework\serializers.py", line 429, in run_validation
    value = self.validate(value)
  File "C:\Users\emedhub\Desktop\html\Project\BE\castingiq jango\castingiq\master\serializer.py", line 14, in validate
    return CodeAutoGenerate.generate_code(self.Meta.model, attrs, prefix='EMT', id=self.id)
AttributeError: 'pattern_typeSerializer' object has no attribute 'id'
[2025-04-26 12:45:25] ERROR in my_logger: Error in GET method: 'pattern_typeSerializer' object has no attribute 'id'
Traceback (most recent call last):
  File "C:\Users\emedhub\Desktop\html\Project\BE\castingiq jango\castingiq\master\views.py", line 32, in post
    is_valid = serializer.is_valid(raise_exception=True)
  File "C:\Users\emedhub\AppData\Local\Programs\Python\Python310\lib\site-packages\rest_framework\serializers.py", line 227, in is_valid
    self._validated_data = self.run_validation(self.initial_data)
  File "C:\Users\emedhub\AppData\Local\Programs\Python\Python310\lib\site-packages\rest_framework\serializers.py", line 429, in run_validation
    value = self.validate(value)
  File "C:\Users\emedhub\Desktop\html\Project\BE\castingiq jango\castingiq\master\serializer.py", line 14, in validate
    return CodeAutoGenerate.generate_code(self.Meta.model, attrs, prefix='EMT', id=self.id)
AttributeError: 'pattern_typeSerializer' object has no attribute 'id'

During handling of the above exception, another exception occurred:

Traceback (most recent call last):
  File "C:\Users\emedhub\Desktop\html\Project\BE\castingiq jango\castingiq\master\views.py", line 34, in post
    serializer.is_valid()
  File "C:\Users\emedhub\AppData\Local\Programs\Python\Python310\lib\site-packages\rest_framework\serializers.py", line 227, in is_valid
    self._validated_data = self.run_validation(self.initial_data)
  File "C:\Users\emedhub\AppData\Local\Programs\Python\Python310\lib\site-packages\rest_framework\serializers.py", line 429, in run_validation
    value = self.validate(value)
  File "C:\Users\emedhub\Desktop\html\Project\BE\castingiq jango\castingiq\master\serializer.py", line 14, in validate
    return CodeAutoGenerate.generate_code(self.Meta.model, attrs, prefix='EMT', id=self.id)
AttributeError: 'pattern_typeSerializer' object has no attribute 'id'
[2025-04-26 12:52:33] ERROR in my_logger: Error in GET method: name 'serializer' is not defined
Traceback (most recent call last):
  File "C:\Users\emedhub\Desktop\html\Project\BE\castingiq jango\castingiq\master\views.py", line 31, in post
    is_valid = serializer.is_valid(raise_exception=True)
NameError: name 'serializer' is not defined

During handling of the above exception, another exception occurred:

Traceback (most recent call last):
  File "C:\Users\emedhub\Desktop\html\Project\BE\castingiq jango\castingiq\master\views.py", line 33, in post
    serializer.is_valid()
NameError: name 'serializer' is not defined
[2025-04-26 12:53:13] ERROR in my_logger: Error in GET method: name 'serializer' is not defined
Traceback (most recent call last):
  File "C:\Users\emedhub\Desktop\html\Project\BE\castingiq jango\castingiq\master\views.py", line 31, in post
    is_valid = serializer.is_valid(raise_exception=True)
NameError: name 'serializer' is not defined

During handling of the above exception, another exception occurred:

Traceback (most recent call last):
  File "C:\Users\emedhub\Desktop\html\Project\BE\castingiq jango\castingiq\master\views.py", line 33, in post
    serializer.is_valid()
NameError: name 'serializer' is not defined
[2025-04-26 13:05:12] ERROR in my_logger: Error in GET method: 'Manager' object has no attribute 'save'
Traceback (most recent call last):
  File "C:\Users\emedhub\Desktop\html\Project\BE\castingiq jango\castingiq\master\views.py", line 81, in put
    pattern_type.objects.save(**pattern_type_data)
AttributeError: 'Manager' object has no attribute 'save'
[2025-04-27 02:06:51] ERROR in module: Error in GET method: (1146, "Table 'django.module_module' doesn't exist")
Traceback (most recent call last):
  File "C:\Users\emedhub\AppData\Local\Programs\Python\Python310\lib\site-packages\django\db\backends\utils.py", line 105, in _execute
    return self.cursor.execute(sql, params)
  File "C:\Users\emedhub\AppData\Local\Programs\Python\Python310\lib\site-packages\django\db\backends\mysql\base.py", line 76, in execute
    return self.cursor.execute(query, args)
  File "C:\Users\emedhub\AppData\Local\Programs\Python\Python310\lib\site-packages\MySQLdb\cursors.py", line 179, in execute
    res = self._query(mogrified_query)
  File "C:\Users\emedhub\AppData\Local\Programs\Python\Python310\lib\site-packages\MySQLdb\cursors.py", line 330, in _query
    db.query(q)
  File "C:\Users\emedhub\AppData\Local\Programs\Python\Python310\lib\site-packages\MySQLdb\connections.py", line 261, in query
    _mysql.connection.query(self, query)
MySQLdb.ProgrammingError: (1146, "Table 'django.module_module' doesn't exist")

The above exception was the direct cause of the following exception:

Traceback (most recent call last):
  File "C:\Users\emedhub\Desktop\html\Project\BE\castingiq jango\castingiq\module\views.py", line 16, in get
    paginator = CustomPaginator(serializer.data,page_size=5,use_serializer=True)
  File "C:\Users\emedhub\AppData\Local\Programs\Python\Python310\lib\site-packages\rest_framework\serializers.py", line 768, in data
    ret = super().data
  File "C:\Users\emedhub\AppData\Local\Programs\Python\Python310\lib\site-packages\rest_framework\serializers.py", line 253, in data
    self._data = self.to_representation(self.instance)
  File "C:\Users\emedhub\AppData\Local\Programs\Python\Python310\lib\site-packages\rest_framework\serializers.py", line 686, in to_representation
    return [
  File "C:\Users\emedhub\AppData\Local\Programs\Python\Python310\lib\site-packages\django\db\models\query.py", line 400, in __iter__
    self._fetch_all()
  File "C:\Users\emedhub\AppData\Local\Programs\Python\Python310\lib\site-packages\django\db\models\query.py", line 1928, in _fetch_all
    self._result_cache = list(self._iterable_class(self))
  File "C:\Users\emedhub\AppData\Local\Programs\Python\Python310\lib\site-packages\django\db\models\query.py", line 91, in __iter__
    results = compiler.execute_sql(
  File "C:\Users\emedhub\AppData\Local\Programs\Python\Python310\lib\site-packages\django\db\models\sql\compiler.py", line 1562, in execute_sql
    cursor.execute(sql, params)
  File "C:\Users\emedhub\AppData\Local\Programs\Python\Python310\lib\site-packages\django\db\backends\utils.py", line 122, in execute
    return super().execute(sql, params)
  File "C:\Users\emedhub\AppData\Local\Programs\Python\Python310\lib\site-packages\django\db\backends\utils.py", line 79, in execute
    return self._execute_with_wrappers(
  File "C:\Users\emedhub\AppData\Local\Programs\Python\Python310\lib\site-packages\django\db\backends\utils.py", line 92, in _execute_with_wrappers
    return executor(sql, params, many, context)
  File "C:\Users\emedhub\AppData\Local\Programs\Python\Python310\lib\site-packages\django\db\backends\utils.py", line 100, in _execute
    with self.db.wrap_database_errors:
  File "C:\Users\emedhub\AppData\Local\Programs\Python\Python310\lib\site-packages\django\db\utils.py", line 91, in __exit__
    raise dj_exc_value.with_traceback(traceback) from exc_value
  File "C:\Users\emedhub\AppData\Local\Programs\Python\Python310\lib\site-packages\django\db\backends\utils.py", line 105, in _execute
    return self.cursor.execute(sql, params)
  File "C:\Users\emedhub\AppData\Local\Programs\Python\Python310\lib\site-packages\django\db\backends\mysql\base.py", line 76, in execute
    return self.cursor.execute(query, args)
  File "C:\Users\emedhub\AppData\Local\Programs\Python\Python310\lib\site-packages\MySQLdb\cursors.py", line 179, in execute
    res = self._query(mogrified_query)
  File "C:\Users\emedhub\AppData\Local\Programs\Python\Python310\lib\site-packages\MySQLdb\cursors.py", line 330, in _query
    db.query(q)
  File "C:\Users\emedhub\AppData\Local\Programs\Python\Python310\lib\site-packages\MySQLdb\connections.py", line 261, in query
    _mysql.connection.query(self, query)
django.db.utils.ProgrammingError: (1146, "Table 'django.module_module' doesn't exist")
[2025-04-27 02:27:56] ERROR in module: Error in GET method: The field 'SubModule' was declared on serializer ModuleWithSubmodulesSerializer, but has not been included in the 'fields' option.
Traceback (most recent call last):
  File "C:\Users\emedhub\Desktop\html\Project\BE\castingiq jango\castingiq\module\views.py", line 16, in get
    paginator = CustomPaginator(serializer.data,page_size=5,use_serializer=True)
  File "C:\Users\emedhub\AppData\Local\Programs\Python\Python310\lib\site-packages\rest_framework\serializers.py", line 768, in data
    ret = super().data
  File "C:\Users\emedhub\AppData\Local\Programs\Python\Python310\lib\site-packages\rest_framework\serializers.py", line 253, in data
    self._data = self.to_representation(self.instance)
  File "C:\Users\emedhub\AppData\Local\Programs\Python\Python310\lib\site-packages\rest_framework\serializers.py", line 686, in to_representation
    return [
  File "C:\Users\emedhub\AppData\Local\Programs\Python\Python310\lib\site-packages\rest_framework\serializers.py", line 687, in <listcomp>
    self.child.to_representation(item) for item in iterable
  File "C:\Users\emedhub\AppData\Local\Programs\Python\Python310\lib\site-packages\rest_framework\serializers.py", line 507, in to_representation
    for field in fields:
  File "C:\Users\emedhub\AppData\Local\Programs\Python\Python310\lib\site-packages\rest_framework\serializers.py", line 368, in _readable_fields
    for field in self.fields.values():
  File "C:\Users\emedhub\AppData\Local\Programs\Python\Python310\lib\site-packages\django\utils\functional.py", line 47, in __get__
    res = instance.__dict__[self.name] = self.func(instance)
  File "C:\Users\emedhub\AppData\Local\Programs\Python\Python310\lib\site-packages\rest_framework\serializers.py", line 356, in fields
    for key, value in self.get_fields().items():
  File "C:\Users\emedhub\AppData\Local\Programs\Python\Python310\lib\site-packages\rest_framework\serializers.py", line 1052, in get_fields
    field_names = self.get_field_names(declared_fields, info)
  File "C:\Users\emedhub\AppData\Local\Programs\Python\Python310\lib\site-packages\rest_framework\serializers.py", line 1148, in get_field_names
    assert field_name in fields, (
AssertionError: The field 'SubModule' was declared on serializer ModuleWithSubmodulesSerializer, but has not been included in the 'fields' option.
[2025-04-27 02:28:18] ERROR in module: Error in GET method: The field 'SubModule' was declared on serializer ModuleWithSubmodulesSerializer, but has not been included in the 'fields' option.
Traceback (most recent call last):
  File "C:\Users\emedhub\Desktop\html\Project\BE\castingiq jango\castingiq\module\views.py", line 16, in get
    paginator = CustomPaginator(serializer.data,page_size=5,use_serializer=True)
  File "C:\Users\emedhub\AppData\Local\Programs\Python\Python310\lib\site-packages\rest_framework\serializers.py", line 768, in data
    ret = super().data
  File "C:\Users\emedhub\AppData\Local\Programs\Python\Python310\lib\site-packages\rest_framework\serializers.py", line 253, in data
    self._data = self.to_representation(self.instance)
  File "C:\Users\emedhub\AppData\Local\Programs\Python\Python310\lib\site-packages\rest_framework\serializers.py", line 686, in to_representation
    return [
  File "C:\Users\emedhub\AppData\Local\Programs\Python\Python310\lib\site-packages\rest_framework\serializers.py", line 687, in <listcomp>
    self.child.to_representation(item) for item in iterable
  File "C:\Users\emedhub\AppData\Local\Programs\Python\Python310\lib\site-packages\rest_framework\serializers.py", line 507, in to_representation
    for field in fields:
  File "C:\Users\emedhub\AppData\Local\Programs\Python\Python310\lib\site-packages\rest_framework\serializers.py", line 368, in _readable_fields
    for field in self.fields.values():
  File "C:\Users\emedhub\AppData\Local\Programs\Python\Python310\lib\site-packages\django\utils\functional.py", line 47, in __get__
    res = instance.__dict__[self.name] = self.func(instance)
  File "C:\Users\emedhub\AppData\Local\Programs\Python\Python310\lib\site-packages\rest_framework\serializers.py", line 356, in fields
    for key, value in self.get_fields().items():
  File "C:\Users\emedhub\AppData\Local\Programs\Python\Python310\lib\site-packages\rest_framework\serializers.py", line 1052, in get_fields
    field_names = self.get_field_names(declared_fields, info)
  File "C:\Users\emedhub\AppData\Local\Programs\Python\Python310\lib\site-packages\rest_framework\serializers.py", line 1148, in get_field_names
    assert field_name in fields, (
AssertionError: The field 'SubModule' was declared on serializer ModuleWithSubmodulesSerializer, but has not been included in the 'fields' option.
[2025-06-22 22:53:28] ERROR in my_logger: Error in GET method: 'ReturnDict' object has no attribute 'capitalize'
Traceback (most recent call last):
  File "C:\Users\emedhub\Desktop\html\Project\BE\castingiq jango\castingiq\master\views.py", line 32, in post
    is_valid = serializer.is_valid(raise_exception=True)
  File "C:\Users\emedhub\AppData\Local\Programs\Python\Python310\lib\site-packages\rest_framework\serializers.py", line 235, in is_valid
    raise ValidationError(self.errors)
rest_framework.exceptions.ValidationError: {'description': [ErrorDetail(string='This field is required.', code='required')]}

During handling of the above exception, another exception occurred:

Traceback (most recent call last):
  File "C:\Users\emedhub\Desktop\html\Project\BE\castingiq jango\castingiq\master\views.py", line 36, in post
    return JsonResponse({'status': 'fail', 'message': "Seralizer error"+errors.capitalize().replace('_', ' ')}, status=HTTPStatus.BAD_REQUEST.value)
AttributeError: 'ReturnDict' object has no attribute 'capitalize'
[2025-06-22 22:58:12] ERROR in my_logger: Error in GET method: 'is_draft'
Traceback (most recent call last):
  File "C:\Users\emedhub\Desktop\html\Project\BE\castingiq jango\castingiq\master\views.py", line 48, in post
    message = ('Pattern type saved as draft successfully' if pattern_type_data['is_draft']
KeyError: 'is_draft'
[2025-06-22 23:02:29] ERROR in my_logger: Error in GET method: local variable 'pattern_type_data' referenced before assignment
Traceback (most recent call last):
  File "C:\Users\emedhub\Desktop\html\Project\BE\castingiq jango\castingiq\master\views.py", line 30, in post
    is_draft = pattern_type_data.get('is_draft', False)
UnboundLocalError: local variable 'pattern_type_data' referenced before assignment
[2025-06-23 22:04:17] ERROR in my_logger: Error in GET method: 'id'
Traceback (most recent call last):
  File "D:\castingiq\python\Casting_IQ_BE_PY\master\views.py", line 154, in put
    id = request.data['id']
         ~~~~~~~~~~~~^^^^^^
KeyError: 'id'
[2025-06-23 22:08:19] ERROR in my_logger: Error in GET method: 'id'
Traceback (most recent call last):
  File "D:\castingiq\python\Casting_IQ_BE_PY\master\views.py", line 154, in put
    id = request.data['id']
         ~~~~~~~~~~~~^^^^^^
KeyError: 'id'
[2025-06-23 22:08:58] ERROR in my_logger: Error in GET method: matchPlate_type matching query does not exist.
Traceback (most recent call last):
  File "D:\castingiq\python\Casting_IQ_BE_PY\master\views.py", line 155, in put
    instance = matchPlate_type.objects.get(id=id)
  File "D:\castingiq\python\venv\Lib\site-packages\django\db\models\manager.py", line 87, in manager_method
    return getattr(self.get_queryset(), name)(*args, **kwargs)
           ~~~~~~~~~~~~~~~~~~~~~~~~~~~~~~~~~~^^^^^^^^^^^^^^^^^
  File "D:\castingiq\python\venv\Lib\site-packages\django\db\models\query.py", line 649, in get
    raise self.model.DoesNotExist(
        "%s matching query does not exist." % self.model._meta.object_name
    )
master.models.matchPlate_type.DoesNotExist: matchPlate_type matching query does not exist.
[2025-06-23 22:09:00] ERROR in my_logger: Error in GET method: matchPlate_type matching query does not exist.
Traceback (most recent call last):
  File "D:\castingiq\python\Casting_IQ_BE_PY\master\views.py", line 155, in put
    instance = matchPlate_type.objects.get(id=id)
  File "D:\castingiq\python\venv\Lib\site-packages\django\db\models\manager.py", line 87, in manager_method
    return getattr(self.get_queryset(), name)(*args, **kwargs)
           ~~~~~~~~~~~~~~~~~~~~~~~~~~~~~~~~~~^^^^^^^^^^^^^^^^^
  File "D:\castingiq\python\venv\Lib\site-packages\django\db\models\query.py", line 649, in get
    raise self.model.DoesNotExist(
        "%s matching query does not exist." % self.model._meta.object_name
    )
master.models.matchPlate_type.DoesNotExist: matchPlate_type matching query does not exist.
[2025-06-23 22:09:28] ERROR in my_logger: Error in GET method: cannot access local variable 'matchPlate_type_data' where it is not associated with a value
Traceback (most recent call last):
  File "D:\castingiq\python\Casting_IQ_BE_PY\master\views.py", line 164, in put
    is_draft = matchPlate_type_data.get('is_draft', False)
               ^^^^^^^^^^^^^^^^^^^^
UnboundLocalError: cannot access local variable 'matchPlate_type_data' where it is not associated with a value
[2025-06-23 22:09:30] ERROR in my_logger: Error in GET method: cannot access local variable 'matchPlate_type_data' where it is not associated with a value
Traceback (most recent call last):
  File "D:\castingiq\python\Casting_IQ_BE_PY\master\views.py", line 164, in put
    is_draft = matchPlate_type_data.get('is_draft', False)
               ^^^^^^^^^^^^^^^^^^^^
UnboundLocalError: cannot access local variable 'matchPlate_type_data' where it is not associated with a value
[2025-06-23 22:11:24] ERROR in my_logger: Error in GET method: cannot access local variable 'matchPlate_type_data' where it is not associated with a value
Traceback (most recent call last):
  File "D:\castingiq\python\Casting_IQ_BE_PY\master\views.py", line 164, in put
    is_draft = matchPlate_type_data.get('is_draft', False)
               ^^^^^^^^^^^^^^^^^^^^
UnboundLocalError: cannot access local variable 'matchPlate_type_data' where it is not associated with a value
[2025-06-23 22:12:42] ERROR in my_logger: Error in GET method: cannot access local variable 'matchPlate_type_data' where it is not associated with a value
Traceback (most recent call last):
  File "D:\castingiq\python\Casting_IQ_BE_PY\master\views.py", line 164, in put
    is_draft = matchPlate_type_data.get('is_draft', False)
               ^^^^^^^^^^^^^^^^^^^^
UnboundLocalError: cannot access local variable 'matchPlate_type_data' where it is not associated with a value
[2025-06-23 22:13:05] ERROR in my_logger: Error in GET method: 'id'
Traceback (most recent call last):
  File "D:\castingiq\python\Casting_IQ_BE_PY\master\views.py", line 154, in put
    id = request.data['id']
         ~~~~~~~~~~~~^^^^^^
KeyError: 'id'
[2025-06-23 22:14:40] ERROR in my_logger: Error in GET method: cannot access local variable 'matchPlate_type_data' where it is not associated with a value
Traceback (most recent call last):
  File "D:\castingiq\python\Casting_IQ_BE_PY\master\views.py", line 164, in put
    is_draft = matchPlate_type_data.get('is_draft', False)
               ^^^^^^^^^^^^^^^^^^^^
UnboundLocalError: cannot access local variable 'matchPlate_type_data' where it is not associated with a value
[2025-06-23 22:17:59] ERROR in my_logger: Error in GET method: cannot access local variable 'matchPlate_type_data' where it is not associated with a value
Traceback (most recent call last):
  File "D:\castingiq\python\Casting_IQ_BE_PY\master\views.py", line 164, in put
    is_draft = matchPlate_type_data.get('is_draft', False)
               ^^^^^^^^^^^^^^^^^^^^
UnboundLocalError: cannot access local variable 'matchPlate_type_data' where it is not associated with a value
[2025-06-23 22:23:13] ERROR in my_logger: Error in GET method: cannot access local variable 'pattern_type_data' where it is not associated with a value
Traceback (most recent call last):
  File "D:\castingiq\python\Casting_IQ_BE_PY\master\views.py", line 76, in put
    is_draft = pattern_type_data.get('is_draft', False)
               ^^^^^^^^^^^^^^^^^
UnboundLocalError: cannot access local variable 'pattern_type_data' where it is not associated with a value
[2025-06-23 22:23:20] ERROR in my_logger: Error in GET method: cannot access local variable 'pattern_type_data' where it is not associated with a value
Traceback (most recent call last):
  File "D:\castingiq\python\Casting_IQ_BE_PY\master\views.py", line 76, in put
    is_draft = pattern_type_data.get('is_draft', False)
               ^^^^^^^^^^^^^^^^^
UnboundLocalError: cannot access local variable 'pattern_type_data' where it is not associated with a value
[2025-06-23 22:24:20] ERROR in my_logger: Error in GET method: cannot access local variable 'pattern_type_data' where it is not associated with a value
Traceback (most recent call last):
  File "D:\castingiq\python\Casting_IQ_BE_PY\master\views.py", line 76, in put
    is_draft = pattern_type_data.get('is_draft', False)
               ^^^^^^^^^^^^^^^^^
UnboundLocalError: cannot access local variable 'pattern_type_data' where it is not associated with a value
[2025-06-23 22:25:28] ERROR in my_logger: Error in GET method: cannot access local variable 'pattern_type_data' where it is not associated with a value
Traceback (most recent call last):
  File "D:\castingiq\python\Casting_IQ_BE_PY\master\views.py", line 76, in put
    is_draft = pattern_type_data.get('is_draft', False)
               ^^^^^^^^^^^^^^^^^
UnboundLocalError: cannot access local variable 'pattern_type_data' where it is not associated with a value
[2025-06-23 22:29:51] ERROR in my_logger: Error in GET method: cannot access local variable 'matchPlate_type_data' where it is not associated with a value
Traceback (most recent call last):
  File "D:\castingiq\python\Casting_IQ_BE_PY\master\views.py", line 164, in put
    is_draft = matchPlate_type_data.get('is_draft', False)
               ^^^^^^^^^^^^^^^^^^^^
UnboundLocalError: cannot access local variable 'matchPlate_type_data' where it is not associated with a value
[2025-06-23 22:29:54] ERROR in my_logger: Error in GET method: cannot access local variable 'matchPlate_type_data' where it is not associated with a value
Traceback (most recent call last):
  File "D:\castingiq\python\Casting_IQ_BE_PY\master\views.py", line 164, in put
    is_draft = matchPlate_type_data.get('is_draft', False)
               ^^^^^^^^^^^^^^^^^^^^
UnboundLocalError: cannot access local variable 'matchPlate_type_data' where it is not associated with a value
[2025-06-23 22:31:52] ERROR in my_logger: Error in GET method: cannot access local variable 'matchPlate_type_data' where it is not associated with a value
Traceback (most recent call last):
  File "D:\castingiq\python\Casting_IQ_BE_PY\master\views.py", line 164, in put
    is_draft = matchPlate_type_data.get('is_draft', False)
               ^^^^^^^^^^^^^^^^^^^^
UnboundLocalError: cannot access local variable 'matchPlate_type_data' where it is not associated with a value
[2025-06-23 22:42:49] ERROR in my_logger: Error in GET method: cannot access local variable 'pattern_type_data' where it is not associated with a value
Traceback (most recent call last):
  File "D:\castingiq\python\Casting_IQ_BE_PY\master\views.py", line 164, in put
    is_draft = pattern_type_data.get('is_draft', False)
               ^^^^^^^^^^^^^^^^^
UnboundLocalError: cannot access local variable 'pattern_type_data' where it is not associated with a value
[2025-06-23 22:51:30] ERROR in my_logger: Error in GET method: Field 'id' expected a number but got '1`'.
Traceback (most recent call last):
  File "D:\castingiq\python\venv\Lib\site-packages\django\db\models\fields\__init__.py", line 2123, in get_prep_value
    return int(value)
ValueError: invalid literal for int() with base 10: '1`'

The above exception was the direct cause of the following exception:

Traceback (most recent call last):
  File "D:\castingiq\python\Casting_IQ_BE_PY\master\views.py", line 67, in put
    instance = pattern_type.objects.get(id=id)
  File "D:\castingiq\python\venv\Lib\site-packages\django\db\models\manager.py", line 87, in manager_method
    return getattr(self.get_queryset(), name)(*args, **kwargs)
           ~~~~~~~~~~~~~~~~~~~~~~~~~~~~~~~~~~^^^^^^^^^^^^^^^^^
  File "D:\castingiq\python\venv\Lib\site-packages\django\db\models\query.py", line 635, in get
    clone = self._chain() if self.query.combinator else self.filter(*args, **kwargs)
                                                        ~~~~~~~~~~~^^^^^^^^^^^^^^^^^
  File "D:\castingiq\python\venv\Lib\site-packages\django\db\models\query.py", line 1476, in filter
    return self._filter_or_exclude(False, args, kwargs)
           ~~~~~~~~~~~~~~~~~~~~~~~^^^^^^^^^^^^^^^^^^^^^
  File "D:\castingiq\python\venv\Lib\site-packages\django\db\models\query.py", line 1494, in _filter_or_exclude
    clone._filter_or_exclude_inplace(negate, args, kwargs)
    ~~~~~~~~~~~~~~~~~~~~~~~~~~~~~~~~^^^^^^^^^^^^^^^^^^^^^^
  File "D:\castingiq\python\venv\Lib\site-packages\django\db\models\query.py", line 1501, in _filter_or_exclude_inplace
    self._query.add_q(Q(*args, **kwargs))
    ~~~~~~~~~~~~~~~~~^^^^^^^^^^^^^^^^^^^^
  File "D:\castingiq\python\venv\Lib\site-packages\django\db\models\sql\query.py", line 1609, in add_q
    clause, _ = self._add_q(q_object, self.used_aliases)
                ~~~~~~~~~~~^^^^^^^^^^^^^^^^^^^^^^^^^^^^^
  File "D:\castingiq\python\venv\Lib\site-packages\django\db\models\sql\query.py", line 1641, in _add_q
    child_clause, needed_inner = self.build_filter(
                                 ~~~~~~~~~~~~~~~~~^
        child,
        ^^^^^^
    ...<7 lines>...
        update_join_types=update_join_types,
        ^^^^^^^^^^^^^^^^^^^^^^^^^^^^^^^^^^^^
    )
    ^
  File "D:\castingiq\python\venv\Lib\site-packages\django\db\models\sql\query.py", line 1555, in build_filter
    condition = self.build_lookup(lookups, col, value)
  File "D:\castingiq\python\venv\Lib\site-packages\django\db\models\sql\query.py", line 1385, in build_lookup
    lookup = lookup_class(lhs, rhs)
  File "D:\castingiq\python\venv\Lib\site-packages\django\db\models\lookups.py", line 30, in __init__
    self.rhs = self.get_prep_lookup()
               ~~~~~~~~~~~~~~~~~~~~^^
  File "D:\castingiq\python\venv\Lib\site-packages\django\db\models\lookups.py", line 369, in get_prep_lookup
    return super().get_prep_lookup()
           ~~~~~~~~~~~~~~~~~~~~~~~^^
  File "D:\castingiq\python\venv\Lib\site-packages\django\db\models\lookups.py", line 88, in get_prep_lookup
    return self.lhs.output_field.get_prep_value(self.rhs)
           ~~~~~~~~~~~~~~~~~~~~~~~~~~~~~~~~~~~~^^^^^^^^^^
  File "D:\castingiq\python\venv\Lib\site-packages\django\db\models\fields\__init__.py", line 2125, in get_prep_value
    raise e.__class__(
        "Field '%s' expected a number but got %r." % (self.name, value),
    ) from e
ValueError: Field 'id' expected a number but got '1`'.
[2025-06-23 22:53:36] ERROR in my_logger: Error in GET method: Field 'id' expected a number but got '1`'.
Traceback (most recent call last):
  File "D:\castingiq\python\venv\Lib\site-packages\django\db\models\fields\__init__.py", line 2123, in get_prep_value
    return int(value)
ValueError: invalid literal for int() with base 10: '1`'

The above exception was the direct cause of the following exception:

Traceback (most recent call last):
  File "D:\castingiq\python\Casting_IQ_BE_PY\master\views.py", line 67, in put
    instance = pattern_type.objects.get(id=id)
  File "D:\castingiq\python\venv\Lib\site-packages\django\db\models\manager.py", line 87, in manager_method
    return getattr(self.get_queryset(), name)(*args, **kwargs)
           ~~~~~~~~~~~~~~~~~~~~~~~~~~~~~~~~~~^^^^^^^^^^^^^^^^^
  File "D:\castingiq\python\venv\Lib\site-packages\django\db\models\query.py", line 635, in get
    clone = self._chain() if self.query.combinator else self.filter(*args, **kwargs)
                                                        ~~~~~~~~~~~^^^^^^^^^^^^^^^^^
  File "D:\castingiq\python\venv\Lib\site-packages\django\db\models\query.py", line 1476, in filter
    return self._filter_or_exclude(False, args, kwargs)
           ~~~~~~~~~~~~~~~~~~~~~~~^^^^^^^^^^^^^^^^^^^^^
  File "D:\castingiq\python\venv\Lib\site-packages\django\db\models\query.py", line 1494, in _filter_or_exclude
    clone._filter_or_exclude_inplace(negate, args, kwargs)
    ~~~~~~~~~~~~~~~~~~~~~~~~~~~~~~~~^^^^^^^^^^^^^^^^^^^^^^
  File "D:\castingiq\python\venv\Lib\site-packages\django\db\models\query.py", line 1501, in _filter_or_exclude_inplace
    self._query.add_q(Q(*args, **kwargs))
    ~~~~~~~~~~~~~~~~~^^^^^^^^^^^^^^^^^^^^
  File "D:\castingiq\python\venv\Lib\site-packages\django\db\models\sql\query.py", line 1609, in add_q
    clause, _ = self._add_q(q_object, self.used_aliases)
                ~~~~~~~~~~~^^^^^^^^^^^^^^^^^^^^^^^^^^^^^
  File "D:\castingiq\python\venv\Lib\site-packages\django\db\models\sql\query.py", line 1641, in _add_q
    child_clause, needed_inner = self.build_filter(
                                 ~~~~~~~~~~~~~~~~~^
        child,
        ^^^^^^
    ...<7 lines>...
        update_join_types=update_join_types,
        ^^^^^^^^^^^^^^^^^^^^^^^^^^^^^^^^^^^^
    )
    ^
  File "D:\castingiq\python\venv\Lib\site-packages\django\db\models\sql\query.py", line 1555, in build_filter
    condition = self.build_lookup(lookups, col, value)
  File "D:\castingiq\python\venv\Lib\site-packages\django\db\models\sql\query.py", line 1385, in build_lookup
    lookup = lookup_class(lhs, rhs)
  File "D:\castingiq\python\venv\Lib\site-packages\django\db\models\lookups.py", line 30, in __init__
    self.rhs = self.get_prep_lookup()
               ~~~~~~~~~~~~~~~~~~~~^^
  File "D:\castingiq\python\venv\Lib\site-packages\django\db\models\lookups.py", line 369, in get_prep_lookup
    return super().get_prep_lookup()
           ~~~~~~~~~~~~~~~~~~~~~~~^^
  File "D:\castingiq\python\venv\Lib\site-packages\django\db\models\lookups.py", line 88, in get_prep_lookup
    return self.lhs.output_field.get_prep_value(self.rhs)
           ~~~~~~~~~~~~~~~~~~~~~~~~~~~~~~~~~~~~^^^^^^^^^^
  File "D:\castingiq\python\venv\Lib\site-packages\django\db\models\fields\__init__.py", line 2125, in get_prep_value
    raise e.__class__(
        "Field '%s' expected a number but got %r." % (self.name, value),
    ) from e
ValueError: Field 'id' expected a number but got '1`'.
[2025-06-23 22:55:34] ERROR in my_logger: Error in GET method: Field 'id' expected a number but got '1`'.
Traceback (most recent call last):
  File "D:\castingiq\python\venv\Lib\site-packages\django\db\models\fields\__init__.py", line 2123, in get_prep_value
    return int(value)
ValueError: invalid literal for int() with base 10: '1`'

The above exception was the direct cause of the following exception:

Traceback (most recent call last):
  File "D:\castingiq\python\Casting_IQ_BE_PY\master\views.py", line 67, in put
    instance = pattern_type.objects.get(id=id)
  File "D:\castingiq\python\venv\Lib\site-packages\django\db\models\manager.py", line 87, in manager_method
    return getattr(self.get_queryset(), name)(*args, **kwargs)
           ~~~~~~~~~~~~~~~~~~~~~~~~~~~~~~~~~~^^^^^^^^^^^^^^^^^
  File "D:\castingiq\python\venv\Lib\site-packages\django\db\models\query.py", line 635, in get
    clone = self._chain() if self.query.combinator else self.filter(*args, **kwargs)
                                                        ~~~~~~~~~~~^^^^^^^^^^^^^^^^^
  File "D:\castingiq\python\venv\Lib\site-packages\django\db\models\query.py", line 1476, in filter
    return self._filter_or_exclude(False, args, kwargs)
           ~~~~~~~~~~~~~~~~~~~~~~~^^^^^^^^^^^^^^^^^^^^^
  File "D:\castingiq\python\venv\Lib\site-packages\django\db\models\query.py", line 1494, in _filter_or_exclude
    clone._filter_or_exclude_inplace(negate, args, kwargs)
    ~~~~~~~~~~~~~~~~~~~~~~~~~~~~~~~~^^^^^^^^^^^^^^^^^^^^^^
  File "D:\castingiq\python\venv\Lib\site-packages\django\db\models\query.py", line 1501, in _filter_or_exclude_inplace
    self._query.add_q(Q(*args, **kwargs))
    ~~~~~~~~~~~~~~~~~^^^^^^^^^^^^^^^^^^^^
  File "D:\castingiq\python\venv\Lib\site-packages\django\db\models\sql\query.py", line 1609, in add_q
    clause, _ = self._add_q(q_object, self.used_aliases)
                ~~~~~~~~~~~^^^^^^^^^^^^^^^^^^^^^^^^^^^^^
  File "D:\castingiq\python\venv\Lib\site-packages\django\db\models\sql\query.py", line 1641, in _add_q
    child_clause, needed_inner = self.build_filter(
                                 ~~~~~~~~~~~~~~~~~^
        child,
        ^^^^^^
    ...<7 lines>...
        update_join_types=update_join_types,
        ^^^^^^^^^^^^^^^^^^^^^^^^^^^^^^^^^^^^
    )
    ^
  File "D:\castingiq\python\venv\Lib\site-packages\django\db\models\sql\query.py", line 1555, in build_filter
    condition = self.build_lookup(lookups, col, value)
  File "D:\castingiq\python\venv\Lib\site-packages\django\db\models\sql\query.py", line 1385, in build_lookup
    lookup = lookup_class(lhs, rhs)
  File "D:\castingiq\python\venv\Lib\site-packages\django\db\models\lookups.py", line 30, in __init__
    self.rhs = self.get_prep_lookup()
               ~~~~~~~~~~~~~~~~~~~~^^
  File "D:\castingiq\python\venv\Lib\site-packages\django\db\models\lookups.py", line 369, in get_prep_lookup
    return super().get_prep_lookup()
           ~~~~~~~~~~~~~~~~~~~~~~~^^
  File "D:\castingiq\python\venv\Lib\site-packages\django\db\models\lookups.py", line 88, in get_prep_lookup
    return self.lhs.output_field.get_prep_value(self.rhs)
           ~~~~~~~~~~~~~~~~~~~~~~~~~~~~~~~~~~~~^^^^^^^^^^
  File "D:\castingiq\python\venv\Lib\site-packages\django\db\models\fields\__init__.py", line 2125, in get_prep_value
    raise e.__class__(
        "Field '%s' expected a number but got %r." % (self.name, value),
    ) from e
ValueError: Field 'id' expected a number but got '1`'.
